Workbook

Sheet Mapa de emendas
A1: Ano | C1: Região | D1: Endereço | E1: Beneficiário | F1: CNPJ Beneficiário | G1: Instituição | H1: Nº da Emenda | I1: Área de alocação | J1: Área | K1: Modalidade | L1: Valores destinados | M1: Observação | N1: Tipo da emenda | O1: Situação | P1: Informações adicionais | Q1: Andamento
A2: 2024 | B2: Gramado | C2: =IFERROR(VLOOKUP(B2,'Regiões'!A:B,2,0),"") -> Turismo da Serra | D2: Avenida das Hortênsias, 2029 - Centro, Gramado - RS, CEP 95670-000, Brasil | E2: =G2&" de "&B2 -> Prefeitura Municipal de Gramado | G2: Prefeitura Municipal | H2: 41160005 | I2: Defesa Civil | J2: Defesa Civil | K2: Custeio | L2: 0 | N2: Emenda Individual
A3: 2023 | B3: Rio Grande | D3: Marinha, Rio Grande,RS | E3: Fundo Naval | G3: Fundo Naval | H3: 41160009 | I3: Segurança Pública | J3: Segurança Pública | K3: Custeio | L3: 1200 | N3: Emenda Individual | O3: Recurso pago
A4: 2020 | B4: Bagé | C4: =IFERROR(VLOOKUP(B4,'Regiões'!A:B,2,0),"") -> Sudoeste do Estado | D4: 9ª Delegacia de Polícia Regional – Bagé, Bagé, RS | E4: Polícia Civil | G4: 9ª Delegacia de Polícia Regional – Bagé | H4: 41160010 | I4: Segurança pública | J4: Segurança Pública | K4: Investimento | L4: 12142.85 | N4: Emenda individual | O4: Recurso empenhado. Inexigibilidade de licitação aceita pelo Ministério. Recurso pago em 25/04/2022. De acordo com consulta feita no Transferegov, em 03/04/2024, não é possível afirmar que foi pago. Há dois convênio com o MS vinculados a essa emenda, um deles vigente até 04/2025. Será necessário consultar o órgão para verificar se o valor referente à Polícia Civil de Bagé foi recebido. | P4: Aquisição de Ferramenta Forense para extração, processamento e apoio na análise de dados e informações a partir de plataformas eletrônicas portáteis para estruturar a 9ª Delegacia de Polícia Regional do Interior - Bagé.
A5: 2022 | B5: Barão de Cotegipe | C5: =IFERROR(VLOOKUP(B5,'Regiões'!A:B,2,0),"") -> Alto Uruguai | D5: Prefeitura Municipal, Barão de Cotegipe, RS | E5: Município | G5: Prefeitura Municipal | H5: 41160002 | I5: Saúde (Custeio - PAB) | J5: Saúde | K5: Custeio | L5: 20000 | N5: Emenda Individual | O5: Recurso pago
A6: 2022 | B6: Barão de Cotegipe | C6: =IFERROR(VLOOKUP(B6,'Regiões'!A:B,2,0),"") -> Alto Uruguai | D6: Prefeitura Municipal, Barão de Cotegipe, RS | E6: Prefeitura | G6: Prefeitura Municipal | H6: 41160002 | I6: Saúde (Custeio - PAB) | J6: Saúde | K6: Custeio | L6: 20000 | N6: Emenda individual (processo seletivo 2021) | O6: Recurso pago | P6: Câmara para conservação de vacinas, medicamentos e termolábeis de 420L para a UBS do município.
A7: 2021 | B7: Novo Hamburgo | C7: =IFERROR(VLOOKUP(B7,'Regiões'!A:B,2,0),"") -> Metropolitana de Porto Alegre | D7: 2ª Delegacia de Polícia de Novo Hamburgo , Novo Hamburgo, RS | E7: Polícia Civil | G7: 2ª Delegacia de Polícia de Novo Hamburgo | H7: 41160001 | I7: Segurança pública | J7: Segurança Pública | K7: Investimento | L7: 26383.34 | N7: Emenda individual | O7: Empenhado | P7: Viatura caracterizada tipo SUV.
A8: 2020 | B8: Porto Alegre | C8: =IFERROR(VLOOKUP(B8,'Regiões'!A:B,2,0),"") -> Metropolitana de Porto Alegre | D8: Instituto Geral de Perícias , Porto Alegre, RS | E8: Instituto Geral de Perícias | G8: Instituto Geral de Perícias | H8: 41160008 | I8: Segurança pública | J8: Segurança Pública | K8: Investimento | L8: 26706.33 | N8: Emenda individual | O8: Pregão eletrônio concluído. | P8: Equipamentos e insumos para o IGP: Vials 20 ml com tampa, lacre e septo (50 caixas com 100 unidades).
A9: 2024 | B9: Cerro Branco | C9: =IFERROR(VLOOKUP(B9,'Regiões'!A:B,2,0),"") -> Centro Serra | D9: Avenida Doze de Maio, 520 - Centro, Cerro Branco - RS, CEP 96535-000 | E9: =G9&" de "&B9 -> Prefeitura Municipal de Cerro Branco | G9: Prefeitura Municipal | H9: 41160001 | I9: Custeio - PAB | J9: Saúde | K9: Custeio | L9: 30000 | N9: Emenda Individual
A10: 2023 | B10: Santa Vitória do Palmar | C10: =IFERROR(VLOOKUP(B10,'Regiões'!A:B,2,0),"") -> Zona Sul | D10: Rua Dom Diogo de Souza, 1761, Centro - Santa Vitória do Palmar - RS | E10: APAE | G10: APAE de Santa Vitória do Palmar | I10: Saúde (Custeio) | J10: =LEFT(I10,FIND(" (",I10) - 1) -> Saúde | K10: Custeio | L10: 30514.31 | N10: Emenda de Bancada | O10: Recurso pago | P10: Aquisição de eletrônicos para fins pedagógicos
A11: 2020 | B11: Porto Alegre | C11: =IFERROR(VLOOKUP(B11,'Regiões'!A:B,2,0),"") -> Metropolitana de Porto Alegre | D11: Divisão Estadual de Combate à Corrupção e à Lavagem de Dinheiro, Porto Alegre, RS | E11: Polícia Civil | G11: Divisão Estadual de Combate à Corrupção e à Lavagem de Dinheiro | H11: 41160010 | I11: Segurança pública | J11: Segurança Pública | K11: Investimento | L11: 31428.6 | N11: Emenda individual | O11: Recurso empenhado. Inexigibilidade de licitação aceita pelo Ministério. | P11: Aquisição de Ferramenta Forense de extração e processamento de dados provenientes da navegação na Internet para a estruturação da Divisão Estadual de Combate à Corrupção e à Lavagem de Dinheiro.
A12: 2020 | B12: Porto Alegre | C12: =IFERROR(VLOOKUP(B12,'Regiões'!A:B,2,0),"") -> Metropolitana de Porto Alegre | D12: Instituto Geral de Perícias , Porto Alegre, RS | E12: Instituto Geral de Perícias | G12: Instituto Geral de Perícias | H12: 41160008 | I12: Segurança pública | J12: Segurança Pública | K12: Investimento | L12: 31616.04 | N12: Emenda individual | O12: Pregão eletrônio concluído. | P12: Equipamentos e insumos para o IGP: 2 colunas LC/MS.
A13: 2022 | B13: Campos Borges | C13: =IFERROR(VLOOKUP(B13,'Regiões'!A:B,2,0),"") -> Alta da Serra do Botucarai | D13: Prefeitura Municipal, Campos Borges, RS | E13: Prefeitura | G13: Prefeitura Municipal | H13: 41160002 | I13: Saúde (Custeio - PAB) | J13: Saúde | K13: Custeio | L13: 35000 | N13: Emenda individual (processo seletivo 2021) | O13: Recurso pago | P13: Equipamentos de fisioterapia (barra, eletroestimulador, bicicleta ergométrica, maca hidráulica) para ampliar a rede de atendimento e a oferta de serviços fisioterápicos na UBS do município.
A14: 2023 | B14: Espumoso | C14: =IFERROR(VLOOKUP(B14,'Regiões'!A:B,2,0),"") -> Alta da Serra do Botucarai | D14: R. Vasco da Gama, 277 - Jardim, Espumoso - RS, 99400-000 | E14: APAE | G14: APAE de Espumoso | I14: Saúde (Custeio) | J14: Saúde | K14: Custeio | L14: 35000 | N14: Emenda de Bancada | O14: Recursos pago. | P14: Aquisição e instalação de uma casa de brinquedos para PCD
A15: 2023 | B15: Aratiba | C15: =IFERROR(VLOOKUP(B15,'Regiões'!A:B,2,0),"") -> Alto Uruguai | D15: Aratiba, RS | E15: APAE | G15: APAE de Aratiba | I15: Saúde (Custeio) | J15: Saúde | K15: Custeio | L15: 37480 | N15: Emenda de Bancada | O15: Recurso pago | P15: Instalação de painéis solares
A16: 2021 | B16: Santa Maria | C16: =IFERROR(VLOOKUP(B16,'Regiões'!A:B,2,0),"") -> Centro do Estado | D16: 2ª Delegacia Penitenciária Regional - Santa Maria, Santa Maria, RS | E16: Secretaria de Administração Penitenciária | G16: 2ª Delegacia Penitenciária Regional - Santa Maria | H16: 41160005 | I16: Segurança pública | J16: Segurança Pública | K16: Investimento | L16: 38354.48 | N16: Emenda individual | O16: Recurso pago | P16: Aparelhamento do Grupo de Intervenção Regional (GIR):1 Escudo Balístico, 10 Espingarda PUMP Calibre 12.
A17: 2023 | B17: Bossoroca | C17: =IFERROR(VLOOKUP(B17,'Regiões'!A:B,2,0),"") -> Missões | D17: Rua João Pedro Furtado Fabrício, 068 - Bonfim, Bossoroca - RS, 97850-000 | E17: APAE | G17: APAE de Bossoroca | I17: Saúde (Custeio) | J17: Saúde | K17: Custeio | L17: 39600 | N17: Emenda de Bancada | O17: Recurso pago | P17: Contratação de empresa para realização de aulas de canto e dança
A18: 2020 | B18: Porto Alegre | C18: =IFERROR(VLOOKUP(B18,'Regiões'!A:B,2,0),"") -> Metropolitana de Porto Alegre | D18: Rede de Saúde Div. Prov.- Hosp. Independência, Porto Alegre, RS | E18: Hospital | G18: Rede de Saúde Div. Prov.- Hosp. Independência | H18: 41160005 | I18: Saúde (Custeio - MAC) | J18: Saúde | K18: Custeio | L18: 40000 | N18: Emenda Individual (processo seletivo) | O18: Recurso pago | P18: Recurso para custeio dos serviços de saúde (Média e Alta Complexidade) | Q18: O recurso foi utilizado na aquisição de materiais e medicamentos para o cuidado e tratamento de pacientes com COVID-19, atendidos no Hospital Independência. Itens como EPIS(Itens de Proteção Individual), equipos e insumos hospitalares.
A19: 2023 | B19: Santo Augusto | C19: =IFERROR(VLOOKUP(B19,'Regiões'!A:B,2,0),"") -> Celeiro do Rio Grande | D19: R. José Gutkowski, 490 - São João, Santo Augusto - RS, 98590-000 | E19: APAE | G19: APAE de Santo Augusto | I19: Saúde (Custeio) | J19: =LEFT(I19,FIND(" (",I19) - 1) -> Saúde | K19: Custeio | L19: 40200 | N19: Emenda de Bancada | O19: Recurso pago | P19: Instalação de uma oficina de embelezamento, com duração de 10 meses
A20: 2025 | B20: Campestre da Serra | C20: =IFERROR(VLOOKUP(B20,'Regiões'!A:B,2,0),"") -> Campos de cima da Serra | D20: Secretaria Municipal da Saúde (SMS) – Fundo Municipal da Saúde, Rua Bardini, 215 - Centro, Campestre da Serra - RS, CEP 95255-000 | E20: Fundo Municipal De Saude De Campestre Da Serra - Rs Campestre Da Serra - Rs | F20: 12452816000135 | G20: Prefeitura Municipal | H20: 41160001 | I20: Custeio dos Serviços de Atenção Primária à Saúde | J20: Saúde | K20: Custeio | L20: 40925 | N20: Emenda Individual | P20: Recurso de custeio para apoio aos serviços de atenção básica da saúde do Município
A21: 2020 | B21: Porto Alegre | C21: =IFERROR(VLOOKUP(B21,'Regiões'!A:B,2,0),"") -> Metropolitana de Porto Alegre | D21: Instituto Geral de Perícias , Porto Alegre, RS | E21: Instituto Geral de Perícias | G21: Instituto Geral de Perícias | H21: 41160008 | I21: Segurança pública | J21: Segurança Pública | K21: Investimento | L21: 41388.5 | M21: (na licitação ficou em 27999,00) | N21: Emenda individual | O21: Pregão eletrônio concluído. Pagamento no valor de 27.999,00 realizado em 25/10/2021. O valor unitário das mesas ginecológicas da proposta vencedora ficou em 1.866,00, economizando recursos públicos, já que o valor empenhado era de 2,759,23 por mesa (total de 41.388,50 conforme o Plano de Trabalho) | P21: Equipamentos e insumos para o IGP: 15 mesas ginecológicas.
A22: 2020 | B22: Porto Alegre | C22: =IFERROR(VLOOKUP(B22,'Regiões'!A:B,2,0),"") -> Metropolitana de Porto Alegre | D22: Instituto Geral de Perícias , Porto Alegre, RS | E22: Instituto Geral de Perícias | G22: Instituto Geral de Perícias | H22: 41160008 | I22: Segurança pública | J22: Segurança Pública | K22: Investimento | L22: 41565.73 | N22: Emenda individual | O22: Pregão eletrônio concluído. | P22: Equipamentos e insumos para o IGP: Vials 1,5 -2 ml com tampa e septo (287 caixas com 100 unidades).
A23: 2023 | B23: Rosário do Sul | C23: =IFERROR(VLOOKUP(B23,'Regiões'!A:B,2,0),"") -> Fronteira Oeste | D23: Analvina Severo Coelho, Rosário do Sul - RS, 97590-000 | E23: APAE | G23: APAE de Rosário do Sul | I23: Saúde (Custeio) | J23: =LEFT(I23,FIND(" (",I23) - 1) -> Saúde | K23: Custeio | L23: 44950 | N23: Emenda de Bancada | O23: Recurso pago | P23: Energia solar
A24: 2023 | B24: Bom Retiro do Sul | C24: =IFERROR(VLOOKUP(B24,'Regiões'!A:B,2,0),"") -> Vale do Taquari | D24: Rua Pedro Carneiro Pereira, 204, Centro - Bom Retiro do Sul - RS | E24: APAE | G24: APAE de Bom Retiro do Sul | I24: Saúde (Custeio) | J24: Saúde | K24: Custeio | L24: 49379.28 | N24: Emenda de Bancada | O24: Recurso pago | P24: Placa fotovoltaica
A25: 2023 | B25: Campo Novo | C25: =IFERROR(VLOOKUP(B25,'Regiões'!A:B,2,0),"") -> Celeiro do Rio Grande | D25: Rua Teodomiro Luciano Souza, s/n - Cel. Bicaco, RS, 98580-000 | E25: APAE | G25: APAE de Campo Novo | I25: Saúde (Custeio) | J25: Saúde | K25: Custeio | L25: 49379.28 | N25: Emenda de Bancada | O25: Recurso pago | P25: Usina solar
A26: 2019 | B26: Guaporé | C26: =IFERROR(VLOOKUP(B26,'Regiões'!A:B,2,0),"") -> Encosta Superior do Nordeste | D26: Escola Estadual Técnica Agrícola Guaporé, Guaporé, RS | E26: Escola Agrotécnica | G26: Escola Estadual Técnica Agrícola Guaporé | H26: 71220005 | I26: Educação (escola estadual agrotécnica) | J26: Educação | K26: Investimento | L26: 50000 | N26: Emenda de Bancada (processo seletivo) | O26: Recurso pago | P26: Recurso para a aquisição de implementos agrícolas | Q26: Implementos agrícolas entregues a partir de abril de 2021.
A27: 2020 | B27: Araricá | C27: =IFERROR(VLOOKUP(B27,'Regiões'!A:B,2,0),"") -> Vale dos Sinos | D27: Prefeitura/Hospital Sapiranga, Araricá, RS | E27: Município/hospital mais próximo | G27: Prefeitura/Hospital Sapiranga | I27: Saúde (Custeio - MAC) | J27: Saúde | K27: Custeio | L27: 50000 | N27: Emenda de bancada | O27: Recurso pago | P27: Recursos para custeio do combate à COVID-19 (Média e Alta Complexidade). Como o município não possuía hospital para atender pacientes de COVID-19, e como o recurso era destinado a hospitais, a emenda foi alocada no hospital de referência do município. Prefeitos e hospitais foram comunicados.
A28: 2020 | B28: Canela | C28: =IFERROR(VLOOKUP(B28,'Regiões'!A:B,2,0),"") -> Turismo da Serra | D28: Hospital de Caridade de Canela, Canela, RS | E28: Hospital | G28: Hospital de Caridade de Canela | H28: 7122 0006 | I28: Saúde (Custeio - MAC) | J28: Saúde | K28: Custeio | L28: 50000 | N28: Emenda de Bancada | O28: Recurso pago | P28: Recursos para custeio do combate à COVID-19 (Média e Alta Complexidade)
A29: 2020 | B29: Carazinho | C29: =IFERROR(VLOOKUP(B29,'Regiões'!A:B,2,0),"") -> Alto Jacuí | D29: Hospital Comunitário de Carazinho, Carazinho, RS | E29: Hospital | G29: Hospital Comunitário de Carazinho | H29: 7122 0006 | I29: Saúde (Custeio - MAC) | J29: Saúde | K29: Custeio | L29: 50000 | N29: Emenda de Bancada | O29: Recurso pago | P29: Recursos para custeio do combate à COVID-19 (Média e Alta Complexidade)
A30: 2020 | B30: Gramado | C30: =IFERROR(VLOOKUP(B30,'Regiões'!A:B,2,0),"") -> Turismo da Serra | D30: Hospital Arcanjo São Miguel, Gramado, RS | E30: Hospital | G30: Hospital Arcanjo São Miguel | H30: 7122 0006 | I30: Saúde (Custeio - MAC) | J30: Saúde | K30: Custeio | L30: 50000 | N30: Emenda de Bancada | O30: Recurso pago | P30: Recursos para custeio do combate à COVID-19 (Média e Alta Complexidade)
A31: 2020 | B31: Igrejinha | C31: =IFERROR(VLOOKUP(B31,'Regiões'!A:B,2,0),"") -> Vale do Paranhana | D31: Hospital Bom Pastor, Igrejinha, RS | E31: Hospital | G31: Hospital Bom Pastor | H31: 7122 0006 | I31: Saúde (Custeio - MAC) | J31: Saúde | K31: Custeio | L31: 50000 | N31: Emenda de Bancada | O31: Recurso pago | P31: Recursos para custeio do combate à COVID-19 (Média e Alta Complexidade)
A32: 2020 | B32: Ivoti | C32: =IFERROR(VLOOKUP(B32,'Regiões'!A:B,2,0),"") -> Vale dos Sinos | D32: Hospital São José de Ivoti, Ivoti, RS | E32: Hospital | G32: Hospital São José de Ivoti | H32: 7122 0006 | I32: Saúde (Custeio - MAC) | J32: Saúde | K32: Custeio | L32: 50000 | N32: Emenda de Bancada | O32: Recurso pago | P32: Recursos para custeio do combate à COVID-19 (Média e Alta Complexidade)
A33: 2020 | B33: Marau | C33: =IFERROR(VLOOKUP(B33,'Regiões'!A:B,2,0),"") -> Planalto | D33: Hospital Cristo Redentor Marau, Marau, RS | E33: Hospital | G33: Hospital Cristo Redentor Marau | H33: 7122 0006 | I33: Saúde (Custeio - MAC) | J33: Saúde | K33: Custeio | L33: 50000 | N33: Emenda de Bancada | O33: Recurso pago | P33: Recursos para custeio do combate à COVID-19 (Média e Alta Complexidade)
A34: 2020 | B34: Nova Petrópolis | C34: =IFERROR(VLOOKUP(B34,'Regiões'!A:B,2,0),"") -> Turismo da Serra | D34: Hospital Nova Petrópolis, Nova Petrópolis, RS | E34: Hospital | G34: Hospital Nova Petrópolis | H34: 7122 0006 | I34: Saúde (Custeio - MAC) | J34: Saúde | K34: Custeio | L34: 50000 | N34: Emenda de Bancada | O34: Recurso pago | P34: Recursos para custeio do combate à COVID-19 (Média e Alta Complexidade)
A35: 2020 | B35: Portão | C35: =IFERROR(VLOOKUP(B35,'Regiões'!A:B,2,0),"") -> Vale do Rio Caí | D35: Hospital de Portão, Portão, RS | E35: Hospital | G35: Hospital de Portão | H35: 7122 0006 | I35: Saúde (Custeio - MAC) | J35: Saúde | K35: Custeio | L35: 50000 | N35: Emenda de Bancada | O35: Recurso pago | P35: Recursos para custeio do combate à COVID-19 (Média e Alta Complexidade)
A36: 2020 | B36: Riozinho | C36: =IFERROR(VLOOKUP(B36,'Regiões'!A:B,2,0),"") -> Vale do Paranhana | D36: Hospital Nossa Senhora do Rosário de Riozinho, Riozinho, RS | E36: Hospital | G36: Hospital Nossa Senhora do Rosário de Riozinho | H36: 7122 0006 | I36: Saúde (Custeio - MAC) | J36: Saúde | K36: Custeio | L36: 50000 | N36: Emenda de Bancada | O36: Recurso pago | P36: Recursos para custeio do combate à COVID-19 (Média e Alta Complexidade)
A37: 2020 | B37: Rolante | C37: =IFERROR(VLOOKUP(B37,'Regiões'!A:B,2,0),"") -> Vale do Paranhana | D37: Fundação Hospitalar de Rolante, Rolante, RS | E37: Hospital | G37: Fundação Hospitalar de Rolante | H37: 7122 0006 | I37: Saúde (Custeio - MAC) | J37: Saúde | K37: Custeio | L37: 50000 | N37: Emenda de Bancada | O37: Recurso pago | P37: Recursos para custeio do combate à COVID-19 (Média e Alta Complexidade)
A38: 2020 | B38: Canoas | C38: =IFERROR(VLOOKUP(B38,'Regiões'!A:B,2,0),"") -> Metropolitana de Porto Alegre | D38: Hospital Nossa Senhora das Graças, Canoas, RS | E38: Hospital | G38: Hospital Nossa Senhora das Graças | H38: 41160005 | I38: Saúde (Custeio - MAC) | J38: Saúde | K38: Custeio | L38: 50000 | N38: Emenda Individual | O38: Recurso pago | P38: Recurso para Implemento Mac | Q38: Após cumprimentá-lo, vimos através desta, em resposta ao ofício de n. 137/2020, prestar informações atualizadas sobre o recurso financeiro destinado ao HNSG, em razão de emenda parlamentar impositiva individual de nº 41160005, na área da saúde (custeio) no Orçamento Geral da União 2020, no valor de 50.000,00 (cinqüenta mil reais). Primeiramente, insta apontar que o recurso em questão restou aplicado no Fundo Municipal de Saúde do Município de Canoas/RS, porém, com o não atingimento das metas do Plano Operativo do ano corrente, tais verbas não foram repassadas ao Hospital. A instituição destinatária da emenda parlamentar esteve, durante todo o ano de 2020, em estado crítico financeiro e assistencial, de forma tão grave que desencadeou a declaração de Requisição Administrativa pela Prefeitura Municipal de Canoas, através do Decreto nº 263, de 23 de outubro de 2020, como forma de tentativa de reversão deste quadro. Por isso, apesar de não ter observado o Plano Operativo de 2020 em sua integralidade, tem chances reais e concretas de fazê-lo em 2021, em razão do advento da nova diretoria nomeada pelo Poder Público Municipal, bem como por conta da ampliação de previsão de procedimentos e serviços à população Canoense no novo Plano Operativo. Com isso, haverá, então, o repasse dos recursos financeiros do Fundo Municipal da Saúde ao nosocômio, e a efetiva aplicação destes, possibilitando a prestação de contas requerida.
A39: 2020 | B39: Capão Bonito do Sul | C39: =IFERROR(VLOOKUP(B39,'Regiões'!A:B,2,0),"") -> Nordeste Riograndense | D39: Prefeitura/Hospital São Paulo de Lagoa Vermelha, Capão Bonito do Sul, RS | E39: Município/hospital mais próximo | G39: Prefeitura/Hospital São Paulo de Lagoa Vermelha | H39: 7122 0006 | I39: Saúde (Custeio - MAC) | J39: Saúde | K39: Custeio | L39: 50000 | N39: Emenda de bancada OGU 2020 | O39: Recurso pago | P39: Recursos para custeio do combate à COVID-19 (Média e Alta Complexidade). Como o município não possuía hospital para atender pacientes de COVID-19, e como o recurso era destinado a hospitais, a emenda foi alocada no hospital de referência do município. Prefeitos e hospitais foram comunicados.
A40: 2020 | B40: Lindolfo Collor | C40: =IFERROR(VLOOKUP(B40,'Regiões'!A:B,2,0),"") -> Vale dos Sinos | D40: Prefeitura/Hospital São José Ivoti, Lindolfo Collor, RS | E40: Município/hospital mais próximo | G40: Prefeitura/Hospital São José Ivoti | H40: 7122 0006 | I40: Saúde (Custeio - MAC) | J40: Saúde | K40: Custeio | L40: 50000 | N40: Emenda de bancada OGU 2020 | O40: Recurso pago | P40: Recursos para custeio do combate à COVID-19 (Média e Alta Complexidade). Como o município não possuía hospital para atender pacientes de COVID-19, e como o recurso era destinado a hospitais, a emenda foi alocada no hospital de referência do município. Prefeitos e hospitais foram comunicados.
...

Sheet Página17
A1: Área
A2: Investimento em Atenção Especializada em Saúde | B2: Saúde | C2: 1
A3: Investimento em Atenção Especializada em Saúde | B3: Saúde | C3: 2
A4: Investimento em Atenção Primária à Saúde | B4: Saúde | C4: 3
A5: Investimento em Atenção Primária à Saúde | B5: Saúde | C5: 4
A6: Investimento em Atenção Primária à Saúde | B6: Saúde | C6: 5
A7: Investimento em Atenção Primária à Saúde | B7: Saúde | C7: 6
A8: Investimento em Atenção Primária à Saúde | B8: Saúde | C8: 7
A9: Investimento em Atenção Primária à Saúde | B9: Saúde | C9: 8
A10: Investimento em Atenção Primária à Saúde | B10: Saúde | C10: 9
A11: Investimento em Atenção Primária à Saúde | B11: Saúde | C11: 10
A12: Investimento em Atenção Primária à Saúde | B12: Saúde | C12: 11
A13: Apoio a Projetos de Infraestrutura Turística | B13: Infraestrutura Turística | C13: 12
... A144: Custeio dos Serviços de Média e Alta Complexidade | B144: Saúde | C144: 143

Sheet Página16
A1: Cidade 1 | B1: Cidade
A2: Cerro Branco | B2: =VLOOKUP(A2,E:E,1,0) -> Cerro Branco | C2: 1 | E2: Aceguá | I2: Alvorada | J2: 17
A3: Nova Palma | B3: =VLOOKUP(A3,E:E,1,0) -> Nova Palma | C3: 2 | E3: Água Santa | I3: Alvorada | J3: 84
A4: Sao Sebastiao Do Cai | B4: São Sebastião do Caí | C4: 3 | E4: Agudo | I4: Arambare | J4: 85
A5: Cotipora | B5: Cotiporã | C5: 4 | E5: Ajuricaba | I5: Arroio Do Meio | J5: 95
A6: Gramado | B6: =VLOOKUP(A6,E:E,1,0) -> Gramado | C6: 5 | E6: Alecrim | I6: Arroio Do Meio | J6: 99
A7: Vera Cruz | B7: =VLOOKUP(A7,E:E,1,0) -> Vera Cruz | C7: 6 | E7: Alegrete | I7: Arroio Do Tigre | J7: 62
A8: Bento Goncalves | B8: Bento Gonçalves | C8: 7 | E8: Alegria | I8: Bento Goncalves | J8: 7
A9: Bom Principio | B9: Bom Princípio | C9: 8 | E9: Almirante Tamandaré do Sul | I9: Bento Goncalves | J9: 42
A10: Cachoeira Do Sul | B10: =VLOOKUP(A10,E:E,1,0) -> Cachoeira do Sul | C10: 9 | E10: Alpestre | I10: Bento Goncalves | J10: 76
A11: Dois Irmaos | B11: Dois Irmãos | C11: 10 | E11: Alto Alegre | I11: Bom Principio | J11: 8
A12: Faxinal Do Soturno | B12: =VLOOKUP(A12,E:E,1,0) -> Faxinal do Soturno | C12: 11 | E12: Alto Feliz | I12: Bom Principio | J12: 43
A13: Feliz | B13: =VLOOKUP(A13,E:E,1,0) -> Feliz | C13: 12 | E13: Alvorada | I13: Cachoeira Do Sul | J13: 9
A14: Lajeado | B14: =VLOOKUP(A14,E:E,1,0) -> Lajeado | C14: 13 | E14: Amaral Ferrador | I14: Cachoeira Do Sul | J14: 44
A15: Pelotas | B15: =VLOOKUP(A15,E:E,1,0) -> Pelotas | C15: 14 | E15: Ametista do Sul | I15: Cachoeirinha | J15: 74
A16: Porto Alegre | B16: =VLOOKUP(A16,E:E,1,0) -> Porto Alegre | C16: 15 | E16: André da Rocha | I16: Campo Bom | J16: 49
A17: Santa Cruz Do Sul | B17: =VLOOKUP(A17,E:E,1,0) -> Santa Cruz do Sul | C17: 16 | E17: Anta Gorda | I17: Campo Bom | J17: 86
A18: Alvorada | B18: =VLOOKUP(A18,E:E,1,0) -> Alvorada | C18: 17 | E18: Antônio Prado | I18: Candelaria | J18: 18
A19: Candelaria | B19: Candelária | C19: 18 | E19: Arambaré | I19: Candelaria | J19: 50
A20: Esteio | B20: =VLOOKUP(A20,E:E,1,0) -> Esteio | C20: 19 | E20: Araricá | I20: Canoas | J20: 87
A21: Farroupilha | B21: =VLOOKUP(A21,E:E,1,0) -> Farroupilha | C21: 20 | E21: Aratiba | I21: Caxias Do Sul | J21: 88
A22: Igrejinha | B22: =VLOOKUP(A22,E:E,1,0) -> Igrejinha | C22: 21 | E22: Arroio do Meio | I22: Caxias Do Sul | J22: 110
A23: Ivoti | B23: =VLOOKUP(A23,E:E,1,0) -> Ivoti | C23: 22 | E23: Arroio do Sal | I23: Caxias Do Sul | J23: 121
A24: Jaguari | B24: =VLOOKUP(A24,E:E,1,0) -> Jaguari | C24: 23 | E24: Arroio do Padre | I24: Cerro Branco | J24: 1
A25: Lindolfo Collor | B25: =VLOOKUP(A25,E:E,1,0) -> Lindolfo Collor | C25: 24 | E25: Arroio dos Ratos | I25: Charqueadas | J25: 83
A26: Nova Petropolis | B26: Nova Petrópolis | C26: 25 | E26: Arroio do Tigre | I26: Cotipora | J26: 4
A27: Passo Do Sobrado | B27: =VLOOKUP(A27,E:E,1,0) -> Passo do Sobrado | C27: 26 | E27: Arroio Grande | I27: Dois Irmaos | J27: 10
A28: Picada Cafe | B28: Picada Café | C28: 27 | E28: Arvorezinha | I28: Dois Lajeados | J28: 101
A29: Presidente Lucena | B29: =VLOOKUP(A29,E:E,1,0) -> Presidente Lucena | C29: 28 | E29: Augusto Pestana | I29: Dois Lajeados | J29: 111
A30: Sao Jose Do Herval | B30: São José do Herval | C30: 29 | E30: Áurea | I30: Eldorado Do Sul | J30: 65
A31: Segredo | B31: =VLOOKUP(A31,E:E,1,0) -> Segredo | C31: 30 | E31: Bagé | I31: Eldorado Do Sul | J31: 96
A32: Tres Coroas | B32: Três Coroas | C32: 31 | E32: Balneário Pinhal | I32: Encantado | J32: 55
A33: Estancia Velha | B33: Estância Velha | C33: 32 | E33: Barão | I33: Encantado | J33: 70
A34: Putinga | B34: =VLOOKUP(A34,E:E,1,0) -> Putinga | C34: 33 | E34: Barão de Cotegipe | I34: Estancia Velha | J34: 32
A35: Sapiranga | B35: =VLOOKUP(A35,E:E,1,0) -> Sapiranga | C35: 34 | E35: Barão do Triunfo | I35: Esteio | J35: 19
A36: Montenegro | B36: =VLOOKUP(A36,E:E,1,0) -> Montenegro | C36: 35 | E36: Barracão | I36: Esteio | J36: 51
A37: Sao Vendelino | B37: São Vendelino | C37: 36 | E37: Barra do Guarita | I37: Farroupilha | J37: 20
A38: Santa Maria | B38: =VLOOKUP(A38,E:E,1,0) -> Santa Maria | C38: 37 | E38: Barra do Quaraí | I38: Farroupilha | J38: 52
A39: Sao Luiz Gonzaga | B39: São Luiz Gonzaga | C39: 38 | E39: Barra do Ribeiro | I39: Faxinal Do Soturno | J39: 11
A40: Sao Sebastiao Do Cai | B40: São Sebastião do Caí | C40: 39 | E40: Barra do Rio Azul | I40: Feliz | J40: 12
...

Sheet Página15
A1: Contemplado | B1: Inscrição | C1: Município | D1: Valor solicitado | E1: Valor destinado | F1: Resumo do Projeto | G1: Objeto do Projeto | H1: Endereço de e-mail | I1: População do município | J1: Nome do responsável | K1: Telefone | L1: E-mail | M1: E-mail da Prefeitura | N1: CPF | O1: CNPJ do Fundo Municipal da Saúde | P1: O município possui teto MAC para receber os recursos da emenda parlamentar? | Q1: Total da receita prevista em 2022 (em R$) | R1: Total da receita arrecadada em 2022 (em R$) | S1: Total da despesa liquidada em 2022 (em R$) | T1: Receita corrente líquida em 2022 (em R$) | U1: Despesa com pessoal do Poder Executivo municipal em 2022 (em R$) | V1: A Prefeitura dispõe de profissionais/recursos humanos necessários para operar o equipamento solicitado? | W1: A Prefeitura dispõe de estrutura física necessária para por em funcionamento o equipamento solicitado? | X1: Justificativa do Projeto | Y1: Qual é o objetivo geral do Projeto? | Z1: Detalhe o público-alvo do Projeto | AA1: Descreva os resultados esperados após a execução do Projeto | AB1: Resumo
A2: TRUE | B2: 472 | C2: Campo Bom | D2: R$ 220.400,00 | E2: 220400 | F2: Através da aquisição de 1 (uma) mesa cirúrgica elétrica, 5 (cinco) monitores multiparamétricos, 1 (um)desfibrilador automático de mesa, 1 (um) eletrocautério e 2 (dois) carros-maca hidráulicos, o Município de Ivoti visa a qualificar e ampliar os serviços de média complexidade já ofertados pelo poder público municipal. Com esse projeto, pretende-se atender o usuário de serviços de média complexidade com maior agilidade, qualidade e resolutividade, bem como reduzir as filas de espera para as especialidades pactuadas, impactando positivamente a região. O projeto visa a captar R$ 200.000,00 e atender os usuários do serviços público de saúde. | G2: Aquisição de um Aparelho de Anestesia com Monitor Multiparâmetros | H2: CLEIDIANE@CAMPOBOM.RS.GOV.BR | I2: 66712 | J2: CLEIDIANE SANMARTIM | K2: 51 3598-8689 | L2: CLEIDIANE@CAMPOBOM.RS.GOV.BR | M2: gabinetepmcb@campobom.rs.gov.br | N2: 1845116070 | O2: 11310266000155 | P2: Sim | Q2: R$317.800.000,00 | R2: R$336.969.496,53 | S2: R$314.830.623,62 | T2: R$333.821.771,97 | U2: R$161.712.068,13 - 48,45% | V2: Sim | W2: Sim | X2: O Hospital de Campo Bom Dr. Lauro Réus é referência para a população do município. Conta com 91 leitos de internação e serviço de urgência e emergência 24h referência para uma população regional de 840 mil hab. Atende a linha de cuidado de maternidade risco habitual, cirurgia geral e traumatologia, referência para 140 mil hab. Possui ambulatório de especialidades, procedimentos ambulatoriais, exames de diagnóstico diversos e laboratório de análises clínicas. Os atendimentos são quase 100% a usuários do Sistema Único de Saúde – SUS. O centro cirúrgico do hospital, conta com três salas de cirurgias e apenas duas em operação, devido a falta de equipamentos necessários para funcionamento da terceira. Para abreviar a lista de espera da população por cirurgias eletivas (demanda reprimida), trazendo resolutividade e cuidado a população é necessária a aquisição do carro de anestesia para ativar esta sala e ampliar o número de cirurgias, visando atender a população em fila de espera. | Y2: Ativar a terceira sala de cirurgia eletiva do Hospital que não opera por falta de equipamentos, através da aquisição de um carro de anestesia para abreviar a fila de espera da população. | Z2: Pacientes com necessidade de intervenção cirúrgica, oriundos do Sistema Único de Saúde - SUS da região do Vale do Sinos. | AA2: Espera-se abreviar a fila de espera, através da resolutividade dademanda existente de forma local, gerando cuidado; bem-estar e sobrevida a população. | AB2: Equipamentos para reduzir fila de cirurgias eletivas.
A3: TRUE | B3: 70 | C3: Caxias Do Sul | D3: R$ 300.000,00 | E3: 300000 | F3: O município de Quaraí tem uma população de aproximadamente 24 mil habitantes, pertence a 10ªCoordenadoria Regional de Saúde. Está localizado na região da fronteira oeste do Estado do Rio Grande do Sul, a aproximadamente a 600km da capital gaúcha, 350 km de Santa Maria, 127 km de Uruguaiana ,106 Km de Santana do Livramento, 115Km de Alegrete e a 428km de Ijuí, sendo esses os principais destinos dos atendimentos tratamentos de fora do domícilio via GERCON. E de extrema relevância um meio de transporte adequado e seguro nos atendimentos dos usuários que necessitam realizar procedimentos de caráter eletivos e regulados em situações previsíveis de atenção programada nos municípios de referências disponibilizados. Destaca-se também o atendimento das gestantes de alto risco os quais são realizados no AGAR de Alegrete, sendo um público prioritário e que requer acompanhantes em todos atendimentos. | G3: O objeto do projeto é a aquisição de equipamento de ultrassonografia para a Central de Exames Complementares da Secretaria Municipal de Saúde. | H3: afandrade@caxias.rs.gov.br | I3: 517451 | J3: Andréia Félix Andrade | K3: 54 3290-4487 | L3: afandrade@caxias.rs.gov.br | M3: gabinetesaude@caxias.rs.gov.br | N3: 95472550025 | O3: 10546325000128 | P3: Sim | Q3: R$2.646.757.248,65 | R3: R$2.845.053.101,00 | S3: R$2.718.657.631,66 | T3: R$2.273.901.606,69 | U3: R$1.110.788.132,79 | V3: Sim | W3: Sim | X3: A aquisição do equipamento se justifica pela necessidade de suprir o atendimento à demanda crescente de usuários SUS que registra, atualmente, uma demanda reprimida de exames ecográficos em torno de 6000 unidades. | Y3: O objetivo geral do projeto visa melhorar a qualidade do serviço, permitindo o diagnóstico adequado e o manejo rápido dos pacientes, com consequente preservação da vida. | Z3: Atendimento da população em geral do município de Caxias do Sul e os demais 49 municípios da 5ª CRS. | AA3: Manter e melhorar a qualidade do serviço, atendendo a demanda reprimida de exames ecográficos. | AB3: Equipamento para diagnóstico por imagem ultrassônica.
A4: TRUE | B4: 245 | C4: Encantado | D4: R$ 192.000,00 | E4: 192000 | F4: Aquisição de equipamentos médicos para a CASA DA MULHER, oportunizando melhoria de qualidade de vida a todas mulheres, com diagnóstico rápido, preciso, sendo adquirido os seguintes equipamentos: ultrassom diagnóstico sem aplicação transesofágica; mesa para exames ginecológicos elétrica, colposcópio com camara, monitor; e tela de projeção. | G4: Aquisição de equipamentos | H4: arquitetura@encantado-rs.com.br | I4: 23000 | J4: ANA DELSA TRONCO CIVARDI | K4: 51999954279 | L4: arquitetura@encantado-rs.com.br | M4: arquitetura@encantado-rs.com.br | N4: 24358037020 | O4: 12149722000191 | P4: Sim | Q4: 109000000 | R4: 129912954 | S4: 115229707 | T4: 108672298 | U4: 42487136 | V4: Sim | W4: Sim | X4: Encantado possui somente um Hospital que presta serviços especializados e de emergência para toda a população local e regional. Estamos montando a CASA DA MULHER, onde ofereceremos atendimentos médicos especializados, tendo um atendimento diferenciado. Para tal precisamos que de equipamentos específicos para este atendimento. Com isto, teremos um atendimento de qualidade e preciso, com tecnologia e agilidade. | Y4: Aquisição de equipamentos para disponibilizar nos atendimentos especializados de média complexidade, na CASA DE MULHER. | Z4: Toda as mulheres do Município. | AA4: Melhoria da qualidade de vida das mulheres, com realização de exames específicos, oportunizando rápido encaminhamento para procedimentos e tratamentos médicos necessários | AB4: Equipamentos médicos para a CASA DA MULHER
A5: TRUE | B5: 434 | C5: Flores Da Cunha | D5: R$ 130.000,00 | E5: 130000 | F5: A aquisição das cadeiras odontológicas é muito importante, pois podem ser consideradas um dos principais equipamentos de trabalho dos serviços odontológicos, na qual facilitam o trabalho dos profissionais durante o tratamento bucal, mantendo o paciente confortável para que os procedimentos sejam realizados de forma rápida e precisa. Já, a aquisição do veículo possibilitará melhor atendimento médico e também a ampliação do atendimento domiciliar das equipes de saúde, uma vez que viabilizará a visita aos pacientes que não conseguem se deslocar até a unidade. Além das visitas regulares, a aquisição também possibilita a entrega de medicações, atendimentos em residência e coleta. | G5: Aquisição de um veículo de passeio com câmbio automático e aquisição de duas cadeiras odontológicas para a utilização na UBS - Centro de Saúde Irmã Benedita Zorzi. | H5: dppu@floresdacunha.rs.gov.br | I5: 31352 | J5: Rosiane Machado Pradella | K5: (54)3279-3600 | L5: dppu@floresdacunha.rs.gov.br | M5: planejamento@floresdacunha.rs.gov.br | N5: 1472271009 | O5: 10443938000130 | P5: Sim | Q5: R$125.498.321,00 | R5: R$162.115.259,41 | S5: R$127.730.682,21 | T5: R$138.539.650,06 | U5: R$127.730.682,21 | V5: Sim | W5: Sim | X5: O Projeto que visa a aquisição de 01 veículo de passeio com câmbio automático a ser utilizado na Unidade Básica de Saúde - Centro de Saúde Irmã Benedita Zorzi é muito importante, tendo em vista a necessidade de deslocamentos recorrentes por parte dos servidores a fim de resolver questões da saúde em todo o município. O Centro de Saúde Irmã Benedita Zorzi está em fase de ampliação e estão previstas salas para atendimento odontológico, justificando assim, a aquisição de 2 cadeiras odontológicas para melhor atender a população municipal | Y5: O Objetivo geral do Projeto é proporcionar um melhor atendimento à população municipal, melhorando a qualidade de saúde e de vidas das pessoas. | Z5: Servidores públicos da Prefeitura Municipal que exercem suas funções junto à Unidade Básica de Saúde - Centro de Saúde Irmã Benedita Zorzi, bem como, a população urbana e rural do município que necessita e busca atendimento junto à UBS. | AA5: Cadeiras odontológicas - facilidade para os profissionais durante o tratamento bucal, mantendo o paciente confortável para que os procedimentos sejam realizados de forma rápida e precisa. Veículo - melhor atendimento médico e também, a ampliação do atendimento domiciliar das equipes de saúde, uma vez que permitirá visitas aos pacientes que não podem se deslocar até a unidade. | AB5: Cadeiras odontológicas
A6: TRUE | B6: 197 | C6: Gravataí | D6: R$ 569.226,00 | E6: 569226 | F6: A Política Nacional de Atenção às Urgências é uma política baseada em serviços descentralizados, em regime de gestão pactuada entre as três esferas de governo, tendo os municípios autonomia relativa (Granja et al., 2013; Uchimura et al., 2015). Nossa solicitação de emenda parlamentar visa adquirir uma nova Unidade Móvel de Saúde – SAMU e três equipamentos cardioversores, mediante recursos da União, no valor de R$ 569.226,00. Como resultado, focamos em tecnologia, eficiência, segurança e qualidade nos atendimentos de emergência aos residentes de Gravataí e Cachoeirinha, além de maior segurança à equipe multiprofissional, no exercício de suas funções, contando com aumento de 10% no número de atendimentos realizados pelo SAMU. Por fim, tal emenda tanto qualificará os atendimentos, quanto proporcionará ampliação e racionalização do uso dos recursos públicos, em equipe e manutenção de equipamentos, possibilitando um salto de eficiência na assistência prestada. | G6: Captação de recursos para aquisição de uma Unidade Móvel de Saúde – SAMU e três equipamentos cardioversores, no valor de R$ 569.226,00 (Quinhentos e sessenta e nove mil duzentos e vinte e seis reais). | H6: sms.habilitacoes@gravatai.rs.gov.br | I6: 285564 | J6: Simone Stochero Kummer | K6: (51) 9.9967-5945 | L6: sms.habilitacoes@gravatai.rs.gov.br | M6: sms@gravatai.rs.gov.br | N6: 69371644087 | O6: 12195662000143 | P6: Sim | Q6: R$928.717.000,00 | R6: R$992.424.370,87 | S6: R$959.061.817,33 | T6: R$938.197.669,82 | U6: R$ 384.996.01,02 | V6: Sim | W6: Sim | X6: Nossos equipamentos tem apresentado repetidas necessidades de manutenção, reduzindo tempo de oferta do serviço aos usuários do SUS e/ou oferecendo risco à vida dos pacientes, considerando a imprevisibilidade dos problemas. Um atendimento qualificado e eficaz na Unidade Móvel de Saúde – SAMU-192, articulado com uma boa estrutura para o acolhimento e atendimento sequencial nas Unidades de Pronto Atendimento Municipal – UPAs, é essencial para atender efetivamente às necessidades pontuais de cada paciente. Com a Unidade, reduziremos o tempo de inatividade das equipes técnicas e alcançaremos um progresso de 10% nos atendimentos. Em 2022 tivemos 8.865 atendimentos e 876 transportes medicalizados; temos elevada quilometragem rodada em grande extensão área de cobertura para suporte avançado (512.066 Km²); Unidades Móveis datam de 2013 e 2019. Geograficamente, Gravataí é recortada por 03 precárias rodovias estaduais e 01 rodovia federal, que geram15% dos nossos atendimentos de traumas graves. | Y6: Ampliar eficiência e qualidade na Urgência e Emergência de Gravataí, com tecnologia adequadas, desde o primeiro contato até o momento da estabilização de saúde, nas Unidades de Pronto Atendimento. | Z6: População de 414.860 habitantes, residentes de Gravataí e Cachoeirinha, em suas demandas espontâneas e a partir dos atendimentos gerados em toda a rede básica, especializada e de urgência e emergência, de ambos os territórios municipais. | AA6: Segurança aos pacientes em urgências, com tecnologia qualificada e eficaz. Estima-se aumento de 10% nos atendimentos SAMU-192 e disponibilidade de uma Unidade Móvel como reserva técnica. Redução do desperdício da carga horária multiprofissional, por falta de disponibilidade da Unidade Móvel, bem como redução de custos exorbitantes com serviços de manutenção, provenientes dos cofres municipais. | AB6: Unidade Móvel de Saúde – SAMU e três equipamentos cardioversores
A7: TRUE | B7: 52 | C7: Igrejinha | D7: R$ 300.000,00 | E7: 300000 | F7: O Município de Igrejinha pretende modernizar a sua infraestrutura de TI, adquirindo 40 computadores para interligar as 14 estruturas de saúde do Município, e através da utilização de Sistemas de Informação em Saúde, agilizar o protocolo de atendimento dos pacientes, diminuindo o tempo de espera entre a marcação das consultas, atendimento, regulação e dispensação de medicamentos, além de munir os profissionais de saúde de informações para facilitar o diagnóstico e o tratamento desses pacientes. | G7: Aquisição de Computadores | H7: saude@igrejinha.rs.gov.br | I7: 37770 | J7: Vinicio Jair Wallauer | K7: 51980193111 | L7: viniciowallauer@gmail.com | M7: saude@igrejinha.rs.gov.br | N7: 61672629004 | O7: 12121651000119 | P7: Sim | Q7: R$144.300.000,00 | R7: R$168.083.845,22 | S7: R$170.580.499,53 | T7: R$163.321.270,46 | U7: R$70.761.206,06 | V7: Sim | W7: Sim | X7: A qualificação no atendimento da população na área de saúde requer que todas as estruturas funcionem em rede, de forma síncrona e para isso são necessários além de recursos humanos, equipamentos de processamento e de comunicação de dados. O Município possui 14 unidades de saúde (ESF, UBS, Farmácia, CAPS) e 1 Hospital, que precisam estar interligados para atender a comunidade e isso é feito através de Sistemas de Informação em Saúde. Os Sistemas de Informação em saúde utilizados no município de Igrejinha possibilitam esse atendimento em rede, porém o aperfeiçoamento tecnológico e a expansão da quantidade de dados a serem processados exigem uma infraestrutura de TI mais robusta e atualizada. Sabemos que na área de saúde o tempo é fundamental e para otimizar esse tempo, é necessário que todos os atores do sistema possam ter as informações necessárias em tempo real. | Y7: Adquirir computadores mais modernos e com maior poder de processamento e substituir os equipamentos obsoletos e ultrapassados para possibilitar mais agilidade e modernidade no atendimento à população. | Z7: O Público alvo do projeto são os usuários do SUS em Igrejinha cobertos pela Atenção Primária em Saúde, que representam mais de 90% da população de Igrejinha, perfazendo uma estimativa de mais de 33 mil pessoas. | AA7: Os principais resultados esperados são a agilização dos processos de encaminhamento de consultas e exames, a possibilidade de implantar sistemas mais robustos e aumentar a capacidade de armazenamento de informações, e possibilitar a regulação eletrônica, facilitando a vida dos pacientes do SUS | AB7: 40 computadores para interligar as 14 estruturas de saúde do Município
A8: TRUE | B8: 340 | C8: Ivoti | D8: R$ 200.000,00 | E8: 200000 | F8: A aquisição deste equipamento beneficiará toda a população do Município de Riozinho, na realização dos exames de imagem, evitando deslocamentos, ou se submeter a serviços na inciativa privada; o SUS - Sistema Único de Saúde estará disponível ao acesso da população em geral, mas acima de tudo das gestantes, em seu período de Pré Natal. Outro fator a ser sublinhado é o grande fluxo sazonal de turistas na visitação das atrações naturais, como cascatas e parques, tendo estes, a garantia de atendimento, quando necessário. | G8: Aquisição de 1 (uma) mesa cirúrgica elétrica, 5 (cinco) monitores multiparamétricos, 1 (um)desfibrilador automático de mesa, 1 (um) eletrocautério e 2 (dois) carros-maca hidráulicos. | H8: gabineteivoti@gmail.com | I8: 25068 | J8: Martin Cesar Kalkamnn | K8: 51 3568800 | L8: gabineteivoti@gmail.com | M8: gabinete@ivoti.rs.gov.br | N8: 513320008 | O8: 12104575000133 | P8: Sim | Q8: R$122.230.000,00 | R8: R$141.398.605,32 | S8: R$120.572.331,92 | T8: R$116.754.372,30 | U8: R$49.467.887,18 | V8: Sim | W8: Sim | X8: A Prefeitura de Ivoti, através da Secretaria de Saúde, apesar de ter o compromisso legal de atender a atenção básica, já vem oferecendo serviços de média complexidade, como pequenas cirurgias e atendimentos de especialidades. Com o intuito de qualificar e ampliar esse serviço, está em fase de construção um Centro de Especialidades, o qual exigirá equipamentos que supram as necessidades. | Y8: Qualificar e ampliar os serviços de média complexidade já ofertados pelo poder público municipal. | Z8: Usuários do serviço público de saúde - SUS. | AA8: Atendimento do usuário de serviços de média complexidade com maior agilidade, qualidade e resolutividade. Redução das filas de espera para as especialidades pactuadas, impactando positivamente a região. | AB8: - 1 mesa cirúrgica elétrica - 5 monitores multiparamétricos - 1 desfibrilador automático de mesa - 1 eletrocautério - 2 carros-maca hidráulicos.
A9: TRUE | B9: 183 | C9: Nova Roma Do Sul | D9: R$ 100.000,00 | E9: 100000 | F9: A central de exames, obra que está em finalização e com data para ser inaugurada em março do presente ano, foi idealizada para proporcionar à população de Nova Roma do Sul diversos serviços médicos que até então eram realizados em municípios vizinhos. Fato este que gerava enorme desconforto pois que demandava agendamento de viagens e grande deslocamento de pessoas. Neste sentido, busca-se implementar a central de exames no qual possibilitará o diagnóstico e tratamento mais rápido e com mais comodidade a população nova-romenses. | G9: O recurso solicitado será utilizado para compra dos equipamentos necessários à implementação do serviço de laboratório de análises clínicas, da Central de Exames de Nova Roma do Sul. | H9: tcervo2022@gmail.com | I9: 3430 | J9: TIAGO CERVO | K9: (54) 9.9967-0653 | L9: tcervo2022@gmail.com | M9: planejamento@novaromadosul.rs.gov.br | N9: 2598238052 | O9: 13895113000144 | P9: Sim | Q9: 26300000 | R9: 32123634 | S9: 31098403 | T9: 29850561 | U9: 13129734 | V9: Sim | W9: Sim | X9: Considerando que atualmente são realizados no Município de Nova Roma do Sul, apenas exames de sangue e ecografia, a Central de Exames, viria a sanar uma grande lacuna do serviço de saúde do município, pois contribuiria na agilidade dos diagnósticos, reduzindo viagens e tempo de espera para a realização destes. | Y9: Atendendo à universalidade e à igualdade, o projeto possibilitará maior agilidade no diagnóstico e retorno das consultas. | Z9: Todos os munícipes novaromenses, que dos serviços necessitarem. | AA9: Espera-se zerar a fila de espera por atendimentos, bem como proporcionar uma maior agilidade nos diagnósticos e maior eficácia no tratamento. Também se espera uma diminuição com os custos das viagens que implicam em mão de obra, diárias, combustíveis, manutenção de veículos, entre outros. | AB9: Central de exames para serviços médicos locais eficientes.
A10: TRUE | B10: 391 | C10: Presidente Lucena | D10: R$ 400.000,00 | E10: 400000 | F10: Busca o Projeto reivindicar emenda para aquisição de ambulância uma vez que o único veículo do tipo que o Município possui é velho e não atende mais as necessidades da população. Assim busca-se dotar o Município com ambulância nova que ofereça atendimento humanizado aos pacientes e propicie condições dignas de trabalho à equipe de profissionais. Diante da situação precária da ambulância do Município, pacientes que estão em condição delicada de saúde já não tem mais a garantia de que chegarão em tempo e segurança a seu destino. Tal situação causa aflição tanto a equipe de profissionais envolvidos no transporte, como aos pacientes e familiares dos mesmos. O veículo a ser adquirido irá atender a toda população do Município e eventualmente a outras pessoas que estiverem de passagem por Presidente Lucena e venham a precisar desse serviço. Para adquirir o veículo pleiteado a estimativa de mercado é que o mesmo terá custo de R$400.000,00 | G10: Aquisição de Ambulância | H10: saude@presidentelucena.rs.gov.br | I10: 3300 | J10: Joice Silvinha Froehlich | K10: (51)980413544 | L10: saude@presidentelucena.rs.gov.br | M10: fazenda@presidentelucena.rs.gov.br | N10: 889456003 | O10: 12077214000145 | P10: Sim | Q10: R$26.973.000,00 | R10: R$32.096.580,40 | S10: R$26.490.031,54 | T10: R$27.447.015,48 | U10: R$10.181.973,09 | V10: Sim | W10: Sim | X10: O Município possui um veículo com as características da ambulância a ser adquirida, porém a mesma já é um veículo com mais de 11 anos de uso e alta quilometragem, não oferecendo mais perfeitas condições de uso, não atendendo mais a real necessidade do Município. A ambulância nova a ser adquirida irá tornar mais ágeis os atendimentos, além de oferecer mais segurança e garantia de que o veículo não irá estragar no deslocamento. O Município, como entidade, através da Unidade de Saúde busca atender as demandas da população na própria Unidade Básica, porém casos complexos e de risco a saúde exigem o deslocamento dos pacientes para Hospitais em cidades próximas, região metropolitana e até à Capital. E para estes deslocamentos é necessário que os pacientes sejam conduzidos por meio de ambulância que dê o devido suporte a vida dos mesmos. Atualmente isso já não acontece mais, pois a única ambulância do Município está constantemente estragada em virtude do tempo de uso e o desgaste das peças. | Y10: Dotar o Município de ambulância nova para atender as necessidades do transporte de pacientes. | Z10: Toda população do Município, bem como pessoas de outros cidades que circularem por Presidente Lucena e vierem a precisar do serviço de ambulância. | AA10: Espera-se com a aquisição de ambulância nova, dotar a única Unidade de Saúde do Munícipio de veículo capaz de atender as necessidades dos pacientes. Dotar a saúde pública do Município de condições de oferecer atendimento humanizado aos pacientes e propiciar condições dignas de trabalho à equipe de profissionais encarregada de atender situações de emergência. | AB10: Ambulância
A11: TRUE | B11: 112 | C11: Riozinho | D11: R$ 152.600,00 | E11: 152600 | F11: Equipar toda a UBS com o mínimo de equipamento e material permanente para colocar em funcionamento. | G11: Ultrassom Diagnóstico sem aplicação transesofágica | H11: vanderleivilipetry@gmail.com | I11: 4676 | J11: Ramão Roberto Corso | K11: (51) 9.96116096 | L11: secretaria.saude@pmriozinho.com.br | M11: prefeitura@pmriozinho.com.br | N11: 80517838087 | O11: 11868258000120 | P11: Sim | Q11: R$26.770.226,50 | R11: R$33.140.807,90 | S11: R$29.645.276,10 | T11: R$25.648.260,65 | U11: R$11.598.762,24 | V11: Sim | W11: Sim | X11: Buscar qualificar um serviço na rede de atenção à saúde do usuário na média e alta complexidade, caracterizado pelo bem equipar dos ambulatórios de especialidades médicas, evitando desta forma o deslocamento para outras localidades. Embora o Município tem cotas pactuadas através de CIR e CIB, destes exames, os mesmos são realizados em número reduzido, quando seria possível instalar este equipamento junto ao atendimento da rede de atenção local, sem terceirizações e com atendimento da integralidade da demanda. Necessário grifar também que todo o acompanhamento de Pré-natal, no que tange a realização das ecografias, sem necessidade de qualquer espera ou mesmo para ofertar um número razoável destes exames em um cuidado humanizado, torna a assistência integral às gestantes. | Y11: O objetivo geral do projeto visa beneficiar os usuários, incluindo a manutenção do bem estar e do conforto durante a realização de procedimentos, menos invasivos, o que é fundamental. | Z11: Gestantes em seu Pré-Natal, visando uma gestação saudável e redução da mortalidade neonatal e infantil, como evitar o avanço de outras patologias; Prevenção de câncer de mama, sendo a ultrassonografia o exame capaz de diagnosticar casos assintomáticos, não identificados na mamografia em mulheres jovens, com alta densidade mamária e com histórico familiar. Usuários demandados da Atenção Primária. | AA11: Espera-se a humanização na prestação dos serviços, acesso facilitado para o usuário, zerar qualquer fila de espera pelos exames e economia de gastos em manutenção de frota veicular ao deixarem de buscar atendimento em outras cidades de referência. | AB11: Equipamentos para realização de exames de imagem e cirurgias eletivas.
A12: TRUE | B12: 506 | C12: São Marcos | D12: R$ 249.321,00 | E12: 249321 | F12: Em suma, o projeto visa reduzir a fila de espera significativa para cirurgias eletivas (cirurgia geral, traumatologia, oncologia, etc), decorrente do aumento no número de casos, da demanda reprimida oriunda da pandemia, bem como, pela dificuldade de encaminhamento dos casos aos centros de referência com a ativação da terceira sala de cirurgia do Hospital, que está inoperante por falta de equipamentos necessários a sua operação. Com a aquisição do carro de anestesia, a sala poderá ser ativada, ampliando assim o número de cirurgias, a fim de atender a população em fila de espera. | G12: Ambulância tipo A | H12: secretaria.saude@saomarcos.rs.gov.br | I12: 21756 | J12: MARISTELA LUNEDO | K12: 54999987889 | L12: secretaria.saude@saomarcos.rs.gov.br | M12: gabinete@saomarcos.rs.gov.br | N12: 69574332004 | O12: 12117217000165 | P12: Sim | Q12: R$103.000.000,00 | R12: R$119.629.846,13 | S12: R$104.220.015,24 | T12: R$97.152.366,91 | U12: R$37.748.316,38 | V12: Sim | W12: Sim | X12: As ambulâncias do município estão em constantes manutenções corretivas devido ao uso, atualmente conta com carro alugado e a demanda de transporte aumentou consideravelmente, visto que, temos referencias em outros municípios ( EX: gestantes e traumatologia) sendo assim, necessitamos auxilio para aquisição de uma nova viatura. | Y12: Aquisição de uma ambulância para transporte de pacientes | Z12: Todo paciente que necessite de transporte na horizontal. | AA12: Segurança e conforto para os pacientes e equipe de transporte. | AB12: Ambulância tipo A
A13: TRUE | B13: 256 | C13: Sapiranga | D13: R$ 843.316,00 | E13: 843316 | F13: O município de Sapiranga/RS, por meio deste, solicita Emenda Parlamentar no valor de R$ 843.316,00, para aquisição de 1 equipamento de Raio-X com CR, 1 impressora dry, 6 computadores básicos, 1 computador Desktop Avançado, 2 aparelhos de ar condicionado, 1 escada 2 degraus, 2 cadeiras, 1 banqueta e 1 cadeira de rodízios. Os equipamentos serão utilizados na UPA I 24 horas do município, para realização de exames de Raio-X nos atendimentos de urgência e emergência, aos usuários deste serviço, com digitalização e envio das imagens para o sistema informatizado, compartilhados e acessíveis em computadores, possibilitando maior agilidade no atendimento, e, ainda, impressão das imagens, maior conforto térmico e melhor acomodação dos pacientes. Sendo assim, solicitamos Emenda Parlamentar para o atendimento qualificado, ágil e eficiente aos usuários do SUS, pois a UPA I 24 horas é um serviço pré-hospitalar de atendimento de urgência e emergência em sistema “portas abertas”. | G13: A proposta tem por objetivo a aquisição de equipamento de Raio-X com CR, computadores básicos, computador (Desktop-Avançado) e impressora dry, aparelhos de ar condicionado 17.000 a 30.000 btus, escada 2 degraus, cadeiras, banqueta e cadeira de rodízios, para a UPA I 24 horas de Sapiranga/RS . | H13: sapsaude@sapiranga.rs.gov.br | I13: 80514 | J13: Marta Regina Klein Reichert | K13: (51) 9.9658-0736 | L13: martareichert@sapiranga.rs.gov.br | M13: gabinete@sapiranga.rs.gov.br | N13: 93934769004 | O13: 11295120000180 | P13: Sim | Q13: R$280.449.196,00 | R13: R$316.046.593,70 | S13: R$253.780.811,63 | T13: R$283.112.373,16 | U13: R$121.551.231,54 | V13: Sim | W13: Sim | X13: A UPA I 24 horas é um serviço público de saúde da rede de urgência e emergência, componente pré-hospitalar fixo, estando habilitada e qualificada junto ao Ministério da Saúde, e dispõe de atendimento médico e exames complementares pertinentes. A aquisição do aparelho de Raio-X com CR proporcionará maior praticidade no atendimento aos pacientes, com realização do exame e diagnóstico no local. Assim, o exame realizado na unidade será disponibilizado em rede, praticamente no mesmo instante, para acesso do médico no consultório e, com a impressora dry, será possível imprimir as imagens do exame, disponibilizando-as ao paciente. A climatização é importante para a conservação e bom funcionamento dos equipamentos, pois necessitam de controle de temperatura, e o cuidado com o bem-estar do paciente depende destas condições, sendo importante a instalação do ar condicionado. Por fim, os itens escada 2 degraus, cadeiras, banqueta e cadeira de rodízios contribuem para adequação da ambiência. | Y13: Aquisição de aparelho de Raio-X com CR, 7 computadores sendo e 1 Desktop avançado, 1 impressora dry, 2 aparelhos de ar condicionado, 1 escada 2 degraus, 2 cadeiras, 1 banqueta e 1 cadeira de rodízios. | Z13: A presente Proposta tem como público-alvo a população sapiranguense e, eventualmente, demais pacientes que acessem ao serviço de urgência e emergência disponibilizado pela UPA I – 24 horas, considerando o sistema de atendimento “portas abertas” da unidade. | AA13: Com a aquisição dos equipamentos objetos dessa proposta vislumbramos atender com agilidade, qualidade e eficiência aos usuários do serviço de urgência e emergência junto à UPA I 24 horas, permitindo a tomada de conduta médica antecipada e minimizando os riscos e o tempo de espera e atendimento, tempo este que pode ser crucial à saúde e à vida do paciente. | AB13: - 1 equipamento de Raio-X com CR - 1 impressora dry - 6 computadores básicos - 1 computador Desktop Avançado - 2 aparelhos de ar condicionado - 1 escada 2 degraus - 2 cadeiras - 1 banqueta - 1 cadeira de rodízios
A14: TRUE | B14: 87 | C14: Taquara | D14: R$ 320.000,00 | E14: 320000 | F14: A aquisição de um veículo de Transporte Sanitário, com acessibilidade, irá ajudar a garantir o transporte seguro dos pacientes, inclusive cadeirantes, para o comparecimento à consultas e exames. Com a aquisição do veículo, a Secretaria diminuirá os custos com transporte, tendo em vista que fará um número menor de viagens, já que o veículo possuí mais lugares que os veículos que atualmente realizam esses transportes. | G14: Aquisição de um Veículo de Transporte Sanitário (com Acessibilidade - 1 Cadeirante). | H14: planej04@taquara.rs.gov.br | I14: 57740 | J14: Valentine Vaccari Dall'Acqua | K14: (51) 9.9992-6965 | L14: valentinedallacqua@gmail.com | M14: planej04@taquara.rs.gov.br | N14: 2515145019 | O14: 11940346000196 | P14: Sim | Q14: R$197.907.923,22 | R14: R$229.273.987,85 | S14: R$213.170.171,63 | T14: R$181.747.422,26 | U14: R$104.002.024,13 | V14: Sim | W14: Sim | X14: O município de Taquara está localizado na Região 6 - Paranhana - de Saúde, que é composta por 8 municípios. Todos municípios possuem hospitais e foi construído um processo de regionalização onde cada hospital assumiu um tipo de vocacionamento. Os paciente do município são atendidos nos municípios da Região e para as especialidades que não estão contempladas regionalmente são encaminhados para outros locais, principalmente Porto Alegre (80 km) e Canoas (72 km). Para comparecer às consultas agendadas os pacientes, em sua grande maioria, recorrem ao transporte sanitário disponibilizado pela Secretaria Municipal de Saúde, seja através de ônibus contratado ou veículos próprios do município. Sem a oferta deste tipo de transporte muitos pacientes não teriam condições de comparecer aos atendimentos médicos necessários para o tratamento, sendo responsabilidade da Secretaria de Saúde oferecer condições para que os pacientes possam comparecer aos atendimentos de forma eficiente e segura. | Y14: Realizar o transporte de pacientes para comparecimento em consultas agendadas, em especialidades médicas ou realização de exames diagnósticos, ofertadas em outros municípios. | Z14: O público-alvo do projeto são os pacientes residentes no município de Taquara que acessam serviços de saúde, seja atendimento médico especializado, sejam exames diagnósticos, em outros municípios. Atualmente são realizadas mensalmente aproximadamente 800 viagens de carro para transporte de pacientes (cerca de 4.000 pessoas). | AA14: O resultado esperado é que seja possível garantir que os pacientes compareçam aos seus atendimentos agendados, evitando faltas no comparecimento à consultas e exames por insuficiência de transporte. | AB14: Veículo de Transporte Sanitário com acessibilidade

Sheet Regiões
A1: Município | B1: Região
A2: Aceguá | B2: Sudoeste do Estado
A3: Água Santa | B3: Nordeste Riograndense
A4: Agudo | B4: Centro do Estado
A5: Ajuricaba | B5: Planalto Médio
A6: Alecrim | B6: Fronteira Noroeste
A7: Alegrete | B7: Fronteira Oeste
A8: Alegria | B8: Fronteira Noroeste
A9: Almirante Tamandaré do Sul | B9: Alto Jacuí
A10: Alpestre | B10: Zona da Produção
A11: Alto Alegre | B11: Alta da Serra do Botucarai
A12: Alto Feliz | B12: Vale do Rio Caí
... A498: Xangri-lá | B498: Litoral Norte

